Workbook

Sheet Instructions
A3: Sheets in this workbook:
A4: • Orders_Extract - 4,000-row sample of orders joined with customer info (deliberately messy)
A5: • OrderLines_Extract - 4,000-row sample of order line items joined with product & order info
A7: Your tasks (see the full Student Brief for details):
A8: 1. On a COPY of each sheet, clean obvious data-quality issues you find (inconsistent state names/casing,
A9: stray whitespace, mixed-case status/tier text, negative shipping costs, etc.). Use formulas
A10: (TRIM, PROPER, UPPER, IF, IFERROR) - do not just retype values by hand.
A11: 2. Build at least TWO PivotTables: e.g. (a) total revenue by state and membership_tier,
A12: (b) total quantity and revenue by product category and channel.
A13: 3. Build at least ONE PivotChart from one of your PivotTables.
A14: 4. Add a 'Descriptive_Stats' sheet with AVERAGE, MEDIAN, STDEV, MIN, MAX and COUNT for total_amount
A15: and shipping_cost, computed with formulas (not typed-in numbers).
... A20: analysis in later phases must use the FULL CSV files in data/raw/, not this workbook.

Sheet Orders_Extract
B1: customer_id | C1: order_date | D1: channel | E1: order_status | F1: payment_method | G1: shipping_cost | H1: discount_pct | I1: total_amount | J1: first_name | K1: last_name | L1: state | M1: membership_tier | N1: signup_date
A2: ORD127194 | B2: CUST001908 | C2: 2025-05-31 | D2: In-Store | E2: Completed | F2: PayPal | G2: 5.99 | H2: 0 | I2: 607.63 | J2: Ashley | K2: Hester | L2: Indiana | M2: BRONZE | N2: 05/18/2025
A3: ORD109227 | B3: CUST004626 | C3: 2025-08-22 | D3: Mobile App | E3: Returned | F3: Gift Card | G3: 0 | H3: 15 | I3: 1195.8 | J3: Leah | K3: Whitaker | L3: WISCONSIN | M3: gold | N3: 2024-03-22
A4: ORD109077 | B4: CUST000733 | C4: 2024-09-16 | D4: Online | E4: Cancelled | F4: Debit Card | G4: 4.99 | H4: 0 | I4: 2670.39 | J4: Bryan | K4: Holt | L4: GA | M4: Gold | N4: 2022-12-27
A5: ORD100396 | B5: CUST002155 | C5: 2025-04-14 | D5: Mobile App | E5: Pending | F5: Credit Card | G5: 0 | H5: 0 | I5: 2207.73 | J5: Dennis | K5: Rowe | L5: PA | M5: Bronze | N5: 2025-04-02
A6: ORD113973 | B6: CUST001459 | C6: 2023-10-12 | D6: Online | E6: Completed | F6: PayPal | G6: 0 | H6: 0 | I6: 755.59 | J6: Brett | K6: Ashley | L6: NY | M6: silver | N6: 2022-12-15
A7: ORD126188 | B7: CUST005599 | C7: 2023-07-19 | D7: Mobile App | E7: Pending | F7: Gift Card | G7: 4.99 | H7: 0 | I7: 608.18 | J7: Molly | K7: Serrano | L7: Wisconsin | M7: gold | N7: 2021-01-04
A8: ORD119947 | B8: CUST005844 | C8: 2026-05-04 | D8: Mobile App | E8: Completed | F8: Debit Card | G8: 0 | H8: 0 | I8: 2447.22 | J8: William | K8: Luna | L8: OH | M8: BRONZE | N8: 2024-08-31
A9: ORD116133 | B9: CUST001071 | C9: 2022-02-02 | D9: Online | E9: Completed | F9: Gift Card | G9: 0 | H9: 5 | I9: 1552.8 | J9: James | K9: Mullen | L9: Michigan | M9: Silver | N9: 2020-09-24
A10: ORD125114 | B10: CUST005141 | C10: 2026-03-10 | D10: Online | E10: Completed | F10: PayPal | G10: 12.99 | H10: 5 | I10: 458.04 | J10: Jose | K10: Owens | L10: New York | M10: Platinum | N10: 2026-03-05
A11: ORD103892 | B11: CUST004318 | C11: 2025-02-22 | D11: Online | E11: Completed | F11: Debit Card | G11: 12.99 | H11: 0 | I11: 130.99 | J11: Monica | K11: Williams | L11: NC | M11: BRONZE | N11: 2024-12-21
A12: ORD118451 | B12: CUST004089 | C12: 2024-10-02 | D12: Online | E12: Completed | F12: Store Credit | G12: 0 | H12: 10 | I12: 1380.19 | J12: Laura | K12: Parrish | L12: Missouri | M12: Platinum | N12: 2022-08-31
A13: ORD107271 | B13: CUST004048 | C13: 2024-01-09 | D13: Mobile App | E13: Completed | F13: Store Credit | G13: 7.99 | H13: 0 | I13: 944.14 | J13: Eric | K13: Mosley | L13: tx | M13: BRONZE | N13: 2020-10-21
... A75: ORD124934 | B75: CUST005527 | C75: 2024-07-17 | D75: Mobile App | E75: Completed | F75: Debit Card | G75: 4.99 | H75: 0 | I75: 392.77 | J75: Terrance | K75: Donovan | L75: va | M75: gold | N75: 2024-06-21
A76: ORD101585 | B76: CUST006044 | D76: In-Store | E76: Completed | F76: PayPal | G76: 4.99 | H76: 0 | I76: 932.21 | J76: Jonathan | K76: Collins | L76: Pennsylvania | M76: platinum | N76: 2021-11-11
A77: ORD101196 | B77: CUST002069 | C77: 2025-05-11 | D77: Online | E77: Completed | F77: Credit Card | G77: 7.99 | H77: 15 | I77: 2816.23 | J77: Crystal | K77: Wilkinson | L77: ga | M77: BRONZE | N77: 2020-09-24
A78: ORD119297 | B78: CUST000059 | C78: 2023-05-08 | D78: In-Store | E78: Completed | F78: Gift Card | G78: 0 | H78: 0 | I78: 470.35 | J78: Joseph | K78: Martinez | L78: NC | M78: bronze | N78: 2021-05-02
A79: ORD112147 | B79: CUST000033 | C79: 2025-04-02 | D79: Mobile App | E79: Completed | F79: Credit Card | G79: 0 | H79: 0 | I79: 994.12 | J79: Ashley | K79: Barnett | L79: PA | M79: silver | N79: 2023-07-20
A80: ORD126366 | B80: CUST004904 | C80: 2024-06-04 | D80: Online | E80: Returned | F80: Debit Card | G80: 4.99 | H80: 0 | I80: 1079.59 | J80: Robert | K80: Allen | L80: VA | M80: SILVER | N80: 2022-07-14
A81: ORD124737 | B81: CUST000122 | C81: 2023-10-30 | D81: In-Store | E81: Completed | F81: Gift Card | G81: 4.99 | H81: 0 | I81: 1876.46 | J81: Christopher | K81: Bruce | L81: IL | M81: Bronze | N81: 2022-08-08
A82: ORD125909 | B82: CUST003077 | C82: 2025-12-29 | D82: Mobile App | E82: Completed | F82: Gift Card | G82: 7.99 | H82: 0 | I82: 1131.9 | J82: Jesse | K82: Drake | L82: md | M82: BRONZE | N82: 2025-01-02
A83: ORD114677 | B83: CUST005677 | C83: 2026-02-09 | D83: Online | E83: Completed | F83: Debit Card | G83: 5.99 | H83: 0 | I83: 2524.15 | J83: Tara | K83: Jenkins | L83: OH | M83: Bronze | N83: 2023-07-20
A84: ORD110512 | B84: CUST006072 | C84: 2025-07-26 | D84: In-Store | E84: Completed | F84: Store Credit | G84: 0 | H84: 0 | I84: 3822.57 | J84: Tracy | K84: Haley | L84: ARIZONA | M84: bronze | N84: 2025-07-26
A85: ORD117570 | B85: CUST004321 | C85: 2023-02-01 | D85: In-Store | E85: Completed | F85: Gift Card | G85: 7.99 | H85: 0 | I85: 984.33 | J85: Timothy | K85: Garcia | L85: NY | M85: bronze | N85: 2020-09-11
A86: ORD106915 | B86: CUST001841 | C86: 2024-05-20 | D86: In-Store | E86: Cancelled | F86: Credit Card | G86: 0 | H86: 0 | I86: 2786.87 | J86: Peter | K86: Phillips | L86: OH | M86: Bronze | N86: 2024-02-07
A87: ORD120520 | B87: CUST003431 | C87: 2024-10-01 | D87: Mobile App | E87: Completed | F87: PayPal | G87: 7.99 | H87: 5 | I87: 740.23 | J87: Yvonne | K87: Short | L87: AZ | M87: Bronze | N87: 2024-08-16
A88: ORD113169 | B88: CUST001610 | D88: Mobile App | E88: Completed | F88: Store Credit | G88: 12.99 | H88: 0 | I88: 2780.86 | J88: Manuel | K88: Brandt | L88: NY | M88: silver | N88: 2024-09-22
A89: ORD101552 | B89: CUST005452 | C89: 2024-08-01 | D89: In-Store | E89: Returned | F89: PayPal | G89: 12.99 | H89: 5 | I89: 6972.53 | J89: Emily | K89: Freeman | L89: mo | M89: bronze | N89: 2023-02-19
A90: ORD122358 | B90: CUST000020 | C90: 2025-06-10 | D90: In-Store | E90: Completed | F90: PayPal | G90: 5.99 | H90: 5 | I90: 928.98 | J90: Monica | K90: Garrison | L90: GA | M90: Silver | N90: 2025-06-05
A91: ORD117828 | B91: CUST003076 | C91: 2025-12-17 | D91: Online | E91: Completed | F91: Gift Card | G91: 0 | H91: 0 | I91: 1644.43 | J91: Benjamin | K91: Phillips | L91: IN | M91: BRONZE | N91: 2022-03-11
A92: ORD109281 | B92: CUST001154 | C92: 2025-03-14 | D92: In-Store | E92: Completed | F92: Store Credit | G92: 7.99 | H92: 0 | I92: 2228.29 | J92: Tracy | K92: Hoffman | L92: Arizona | M92: Gold | N92: 2022-07-21
A93: ORD111335 | B93: CUST004155 | C93: 2022-09-05 | D93: Mobile App | E93: Completed | F93: PayPal | G93: 7.99 | H93: 0 | I93: 3197.45 | J93: Emily | K93: Clark | L93: Missouri | M93: Silver | N93: 2020-11-06
A94: ORD125307 | B94: CUST003733 | C94: 2024-09-25 | D94: In-Store | E94: Completed | F94: Store Credit | G94: 0 | H94: 0 | I94: 2618.68 | J94: Randall | K94: Robinson | L94: MA | M94: GOLD | N94: 2021-07-24
A95: ORD117581 | B95: CUST004860 | C95: 2026-02-25 | D95: Mobile App | E95: Completed | F95: Debit Card | G95: 0 | H95: 15 | I95: 1959.91 | J95: Charles | K95: Vaughn | L95: Illinois | M95: bronze | N95: 2025-10-25
A96: ORD110821 | B96: CUST001728 | C96: 2024-11-03 | D96: Mobile App | E96: Completed | F96: Debit Card | G96: 7.99 | H96: 0 | I96: 2221.49 | J96: Katherine | K96: Turner | L96: NJ | M96: Silver | N96: 2024-01-20
A97: ORD126157 | B97: CUST001402 | C97: 2024-05-29 | D97: In-Store | E97: Completed | F97: Gift Card | G97: 12.99 | H97: 0 | I97: 282.76 | J97: Krista | K97: Castillo | L97: wa | M97: BRONZE | N97: 2022-10-02
A98: ORD112720 | B98: CUST002930 | C98: 2025-10-12 | D98: Online | E98: Completed | F98: Credit Card | G98: 0 | H98: 0 | I98: 2488.5 | J98: Cindy | K98: Harris | L98: NY | M98: SILVER | N98: 2025-06-11
A99: ORD119550 | B99: CUST004613 | C99: 2025-06-01 | D99: Mobile App | E99: Completed | F99: Debit Card | G99: 5.99 | H99: 0 | I99: 2064.19 | J99: Kristen | K99: Hoover | L99: NORTH CAROLINA | M99: bronze | N99: 10/30/2022
A100: ORD104485 | B100: CUST005794 | C100: 2022-05-20 | D100: Mobile App | E100: Completed | F100: Credit Card | G100: 4.99 | H100: 0 | I100: 4674.21 | J100: Haley | K100: King | L100: Pennsylvania | M100: bronze | N100: 2021-05-27
... A230: ORD103402 | B230: CUST005373 | C230: 2026-06-10 | D230: Mobile App | E230: Completed | F230: PayPal | G230: 4.99 | H230: 20 | I230: 787.84 | J230: Kayla | K230: Spence | L230: NEW JERSEY | M230: Bronze | N230: 2023-08-03
...

Sheet OrderLines_Extract
A1: order_item_id | B1: order_id | C1: product_id | D1: quantity | E1: unit_price_at_purchase | F1: product_name | G1: category | H1: sub_category | I1: brand | J1: customer_id | K1: order_date | L1: channel | M1: order_status
A2: OI502661 | B2: ORD124764 | C2: PROD1007 | D2: 1 | E2: 119.59 | F2: Meridian Basics Wellness X | G2: Beauty & Personal Care | H2: Wellness | I2: Meridian Basics | J2: CUST002442 | K2: 2024-01-03 | L2: Online | M2: Completed
A3: OI504251 | B3: ORD123647 | C3: PROD1066 | D3: 1 | E3: 92.95 | F3: Northfield Fragrance Max | G3: Beauty & Personal Care | H3: Fragrance | I3: Northfield | J3: CUST003540 | K3: 2025-04-09 | L3: Mobile App | M3: Completed
A4: OI563095 | B4: ORD120357 | C4: PROD1033 | D4: 3 | E4: 147.37 | F4: Crestline Wellness Classic | G4: Beauty & Personal Care | H4: Wellness | I4: Crestline | J4: CUST003336 | K4: 2026-01-09 | L4: Online | M4: Completed
A5: OI508966 | B5: ORD109049 | C5: PROD1211 | D5: 1 | E5: 79.19 | F5: Amberly Bedding | G5: Home & Kitchen | H5: Bedding | I5: Amberly | J5: CUST004023 | K5: 2026-04-04 | L5: In-Store | M5: Completed
A6: OI533946 | B6: ORD127684 | C6: PROD1152 | D6: 3 | E6: 792.04 | F6: Vertex Smartphone Lite | G6: Electronics | H6: Smartphones | I6: Vertex | J6: CUST001077 | K6: 2025-03-21 | L6: Online | M6: Completed
A7: OI540748 | B7: ORD121329 | C7: PROD1163 | D7: 1 | E7: 471.74 | F7: Pinecrest Small Appliances Essential | G7: Home & Kitchen | H7: Small Appliances | I7: Pinecrest | J7: CUST000441 | K7: 2025-12-06 | L7: Mobile App | M7: Completed
A8: OI524525 | B8: ORD104018 | C8: PROD1122 | D8: 3 | E8: 26.31 | F8: Solstice Headphones Essential | G8: Electronics | H8: Headphones | I8: Solstice | J8: CUST001843 | K8: 2024-06-27 | L8: Mobile App | M8: Cancelled
A9: OI504130 | B9: ORD118883 | C9: PROD1158 | D9: 2 | E9: 248.11 | F9: Pinecrest Accessories Plus | G9: Apparel | H9: Accessories | I9: Pinecrest | J9: CUST004873 | K9: 2024-02-15 | L9: Online | M9: Returned
A10: OI568470 | B10: ORD123588 | C10: PROD1106 | D10: 1 | E10: 419.77 | F10: Orion Team Sport Pro | G10: Sports & Outdoors | H10: Team Sports | I10: Orion | J10: CUST003497 | K10: 2023-11-29 | L10: In-Store | M10: Completed
A11: OI571275 | B11: ORD101564 | C11: PROD1071 | D11: 1 | E11: 342.46 | F11: Crestline Cycling Plus | G11: Sports & Outdoors | H11: Cycling | I11: Crestline | J11: CUST002458 | K11: 2025-10-26 | L11: Online | M11: Completed
A12: OI511685 | B12: ORD100958 | C12: PROD1050 | D12: 1 | E12: 36.47 | F12: TrueForm Bedding Essential | G12: Home & Kitchen | H12: Bedding | I12: TrueForm | J12: CUST001439 | K12: 2021-09-12 | L12: Online | M12: Completed
A13: OI520686 | B13: ORD121250 | C13: PROD1011 | D13: 2 | E13: 215.43 | F13: Solstice Small Appliances Lite | G13: Home & Kitchen | H13: Small Appliances | I13: Solstice | J13: CUST002939 | K13: 2025-08-06 | L13: Mobile App | M13: Completed
... A39: OI519957 | B39: ORD113745 | C39: PROD1132 | D39: 1 | E39: 806.53 | F39: Pinecrest Haircare Essential | G39: Beauty & Personal Care | H39: Haircare | I39: Pinecrest | J39: CUST001315 | K39: 2026-06-05 | L39: Online | M39: Completed
A40: OI529577 | B40: ORD118514 | C40: PROD1109 | D40: 4 | F40: Vertex Decor Max | G40: Home & Kitchen | H40: Decor | I40: Vertex | J40: CUST000743 | K40: 2025-09-03 | L40: In-Store | M40: Completed
A41: OI554265 | B41: ORD114522 | C41: PROD1140 | D41: 3 | E41: 629.46 | F41: TrueForm Furniture Classic | G41: Home & Kitchen | H41: Furniture | I41: TrueForm | J41: CUST003690 | K41: 2025-11-20 | L41: In-Store | M41: Completed
A42: OI512680 | B42: ORD105058 | C42: PROD1128 | D42: 1 | E42: 876.84 | F42: Pinecrest Haircare Lite | G42: Beauty & Personal Care | H42: Haircare | I42: Pinecrest | J42: CUST003644 | K42: 2026-01-11 | L42: Online | M42: Completed
A43: OI528901 | B43: ORD122252 | C43: PROD1186 | D43: 2 | E43: 91.47 | F43: Lumen Smart Home | G43: Electronics | H43: Smart Home | I43: Lumen | J43: CUST005202 | K43: 2025-07-25 | L43: Online | M43: Returned
A44: OI549605 | B44: ORD112541 | C44: PROD1035 | D44: 1 | E44: 489.75 | F44: Meridian Basics Women's Clothing Pro | G44: Apparel | H44: Women's Clothing | I44: Meridian Basics | J44: CUST005791 | K44: 2026-03-10 | L44: Online | M44: Completed
A45: OI528722 | B45: ORD108696 | C45: PROD1187 | D45: 1 | E45: 57.19 | F45: Meridian Basics Fitness Equipment Classic | G45: Sports & Outdoors | H45: Fitness Equipment | I45: Meridian Basics | J45: CUST005743 | K45: 2026-04-16 | L45: Mobile App | M45: COMPLETED
A46: OI569949 | B46: ORD126210 | C46: PROD1133 | D46: 1 | E46: 657.83 | F46: Meridian Basics Smart Home Essential | G46: Electronics | H46: Smart Home | I46: Meridian Basics | J46: CUST000126 | K46: 2024-03-23 | L46: Mobile App | M46: Completed
A47: OI559224 | B47: ORD103817 | C47: PROD1095 | D47: 1 | E47: 106.61 | F47: Sabre Cycling X | G47: Sports & Outdoors | H47: Cycling | I47: Sabre | J47: CUST004084 | K47: 2023-04-21 | L47: Mobile App | M47: Completed
A48: OI519731 | B48: ORD120516 | C48: PROD1128 | D48: 2 | E48: 869.4 | F48: Pinecrest Haircare Lite | G48: Beauty & Personal Care | H48: Haircare | I48: Pinecrest | J48: CUST000457 | K48: 2026-06-03 | L48: Mobile App | M48: Completed
A49: OI554521 | B49: ORD115310 | C49: PROD1015 | D49: 1 | E49: 379.13 | F49: Lumen Cookware Lite | G49: Home & Kitchen | H49: Cookware | I49: Lumen | J49: CUST002357 | K49: 2026-01-08 | L49: Online | M49: Cancelled
A50: OI511425 | B50: ORD116255 | C50: PROD1165 | D50: 1 | E50: 348.8 | F50: Solstice Smartphones Plus | G50: Electronics | H50: Smartphones | I50: Solstice | J50: CUST000082 | K50: 2026-04-08 | L50: Online | M50: Completed
A51: OI556807 | B51: ORD115207 | C51: PROD1209 | D51: 1 | E51: 654.81 | F51: Northfield Women's Clothing Lite | G51: Apparel | H51: Women's Clothing | I51: Northfield | J51: CUST001879 | K51: 2024-09-22 | L51: In-Store | M51: completed
A52: OI506530 | B52: ORD119893 | C52: PROD1077 | D52: 1 | E52: 646.09 | F52: TrueForm Women's Clothing Max | G52: Apparel | H52: Women's Clothing | I52: TrueForm | J52: CUST005716 | K52: 2026-01-19 | L52: Online | M52: Pending
... A55: OI559647 | B55: ORD115661 | C55: PROD1094 | D55: 2 | E55: 343.71 | F55: Lumen Women's Clothing Classic | G55: Apparel | H55: Women's Clothing | I55: Lumen | J55: CUST004054 | K55: 2025-08-06 | L55: In-Store | M55: Completed
A56: OI527662 | B56: ORD121895 | C56: PROD1012 | D56: 2 | F56: Northfield Cycling Lite | G56: Sports & Outdoors | H56: Cycling | I56: Northfield | J56: CUST000670 | K56: 2025-07-30 | L56: Mobile App | M56: Completed
A57: OI542769 | B57: ORD124235 | C57: PROD1097 | D57: 1 | E57: 251.04 | F57: BrightPath Accessories Plus | G57: Apparel | H57: Accessories | I57: BrightPath | J57: CUST003734 | K57: 2025-08-21 | L57: Mobile App | M57: Completed
A58: OI505245 | B58: ORD109973 | C58: PROD1126 | D58: 1 | E58: 600.34 | F58: Orion Laptops Essential | G58: Electronics | H58: Laptops | I58: Orion | J58: CUST002084 | K58: 2025-10-10 | L58: Mobile App | M58: Completed
A59: OI547743 | B59: ORD101716 | C59: PROD1045 | D59: 1 | E59: 116.65 | F59: Sabre Furniture | G59: Home & Kitchen | H59: Furniture | I59: Sabre | J59: CUST003035 | K59: 2026-03-30 | L59: In-Store | M59: Completed
A60: OI536586 | B60: ORD104480 | C60: PROD1174 | D60: 1 | E60: 331.83 | F60: TrueForm Tablet | G60: Electronics | H60: Tablets | I60: TrueForm | J60: CUST001871 | K60: 2024-06-11 | L60: In-Store | M60: Completed
A61: OI501685 | B61: ORD119580 | C61: PROD1013 | D61: 1 | E61: 166.51 | F61: TrueForm Fragrance | G61: Beauty & Personal Care | H61: Fragrance | I61: TrueForm | J61: CUST003443 | K61: 2025-03-09 | L61: Mobile App | M61: Completed
A62: OI504903 | B62: ORD118748 | C62: PROD1150 | D62: 1 | E62: 51.07 | F62: Pinecrest Skincare Classic | G62: Beauty & Personal Care | H62: Skincare | I62: Pinecrest | J62: CUST003723 | K62: 2024-12-10 | L62: Online | M62: Completed
A63: OI555894 | B63: ORD117781 | C63: PROD1024 | D63: 1 | E63: 335.28 | F63: Pinecrest Skincare Classic | G63: Beauty & Personal Care | H63: Skincare | I63: Pinecrest | J63: CUST003107 | K63: 2025-01-24 | L63: Online | M63: Completed
A64: OI551522 | B64: ORD107102 | C64: PROD1031 | D64: 1 | E64: 593.48 | F64: Lumen Cookware Essential | G64: Home & Kitchen | H64: Cookware | I64: Lumen | J64: CUST005612 | K64: 2023-10-04 | L64: In-Store | M64: COMPLETED
A65: OI508042 | B65: ORD123000 | C65: PROD1006 | D65: 3 | E65: 526.81 | F65: Crestline Decor | G65: Home & Kitchen | H65: Decor | I65: Crestline | J65: CUST002434 | K65: 2022-05-08 | L65: In-Store | M65: Completed
A66: OI538826 | B66: ORD103387 | C66: PROD1204 | D66: 1 | E66: 516.67 | F66: Lumen Small Appliance X | G66: Home & Kitchen | H66: Small Appliances | I66: Lumen | J66: CUST004681 | K66: 2025-04-09 | L66: Mobile App | M66: Completed
A67: OI533660 | B67: ORD123574 | C67: PROD1125 | D67: 1 | E67: 221.84 | F67: Northfield Team Sports Pro | G67: Sports & Outdoors | H67: Team Sports | I67: Northfield | J67: CUST005151 | K67: 2026-02-21 | L67: Online | M67: Completed
...

Sheet Orders_Clean
A1: order_id | B1: customer_id | C1: order_date | D1: channel | E1: order_status | F1: payment_method | G1: shipping_cost | H1: discount_pct | I1: total_amount | J1: first_name | K1: last_name | L1: state | M1: membership_tier | N1: signup_date | O1: first_name_clean | P1: last_name_clean | Q1: membership_tier_clean | R1: state_clean | S1: order_date_status
A2: ORD127194 | B2: CUST001908 | C2: 2025-05-31 | D2: In-Store | E2: Completed | F2: PayPal | G2: 5.99 | H2: 0 | I2: 607.63 | J2: Ashley | K2: Hester | L2: Indiana | M2: BRONZE | N2: 05/18/2025 | O2: =IF(J2="","UNKNOWN",PROPER(TRIM(J2))) -> Ashley | P2: =IF(K2="","UNKNOWN",PROPER(TRIM(K2))) -> Hester | Q2: =IF(M2="","UNKNOWN",PROPER(TRIM(M2))) -> Bronze | R2: =IFERROR(VLOOKUP(TRIM(L2),State_Mapping!A:B,2,FALSE),"Unknown") -> Indiana | S2: =IF(C2="","Missing","Valid") -> Valid
A3: ORD109227 | B3: CUST004626 | C3: 2025-08-22 | D3: Mobile App | E3: Returned | F3: Gift Card | G3: 0 | H3: 15 | I3: 1195.8 | J3: Leah | K3: Whitaker | L3: WISCONSIN | M3: gold | N3: 2024-03-22
A4: ORD109077 | B4: CUST000733 | C4: 2024-09-16 | D4: Online | E4: Cancelled | F4: Debit Card | G4: 4.99 | H4: 0 | I4: 2670.39 | J4: Bryan | K4: Holt | L4: GA | M4: Gold | N4: 2022-12-27
A5: ORD100396 | B5: CUST002155 | C5: 2025-04-14 | D5: Mobile App | E5: Pending | F5: Credit Card | G5: 0 | H5: 0 | I5: 2207.73 | J5: Dennis | K5: Rowe | L5: PA | M5: Bronze | N5: 2025-04-02
A6: ORD113973 | B6: CUST001459 | C6: 2023-10-12 | D6: Online | E6: Completed | F6: PayPal | G6: 0 | H6: 0 | I6: 755.59 | J6: Brett | K6: Ashley | L6: NY | M6: silver | N6: 2022-12-15 | O6: =IF(J6="","UNKNOWN",PROPER(TRIM(J6))) -> Brett | P6: =IF(K6="","UNKNOWN",PROPER(TRIM(K6))) -> Ashley | Q6: =IF(M6="","UNKNOWN",PROPER(TRIM(M6))) -> Silver | R6: =IFERROR(VLOOKUP(TRIM(L6),State_Mapping!A:B,2,FALSE),"Unknown") -> New York | S6: =IF(C6="","Missing","Valid") -> Valid
A7: ORD126188 | B7: CUST005599 | C7: 2023-07-19 | D7: Mobile App | E7: Pending | F7: Gift Card | G7: 4.99 | H7: 0 | I7: 608.18 | J7: Molly | K7: Serrano | L7: Wisconsin | M7: gold | N7: 2021-01-04
A8: ORD119947 | B8: CUST005844 | C8: 2026-05-04 | D8: Mobile App | E8: Completed | F8: Debit Card | G8: 0 | H8: 0 | I8: 2447.22 | J8: William | K8: Luna | L8: OH | M8: BRONZE | N8: 2024-08-31 | O8: =IF(J8="","UNKNOWN",PROPER(TRIM(J8))) -> William | P8: =IF(K8="","UNKNOWN",PROPER(TRIM(K8))) -> Luna | Q8: =IF(M8="","UNKNOWN",PROPER(TRIM(M8))) -> Bronze | R8: =IFERROR(VLOOKUP(TRIM(L8),State_Mapping!A:B,2,FALSE),"Unknown") -> Ohio | S8: =IF(C8="","Missing","Valid") -> Valid
A9: ORD116133 | B9: CUST001071 | C9: 2022-02-02 | D9: Online | E9: Completed | F9: Gift Card | G9: 0 | H9: 5 | I9: 1552.8 | J9: James | K9: Mullen | L9: Michigan | M9: Silver | N9: 2020-09-24 | O9: =IF(J9="","UNKNOWN",PROPER(TRIM(J9))) -> James | P9: =IF(K9="","UNKNOWN",PROPER(TRIM(K9))) -> Mullen | Q9: =IF(M9="","UNKNOWN",PROPER(TRIM(M9))) -> Silver | R9: =IFERROR(VLOOKUP(TRIM(L9),State_Mapping!A:B,2,FALSE),"Unknown") -> Michigan | S9: =IF(C9="","Missing","Valid") -> Valid
A10: ORD125114 | B10: CUST005141 | C10: 2026-03-10 | D10: Online | E10: Completed | F10: PayPal | G10: 12.99 | H10: 5 | I10: 458.04 | J10: Jose | K10: Owens | L10: New York | M10: Platinum | N10: 2026-03-05 | O10: =IF(J10="","UNKNOWN",PROPER(TRIM(J10))) -> Jose | P10: =IF(K10="","UNKNOWN",PROPER(TRIM(K10))) -> Owens | Q10: =IF(M10="","UNKNOWN",PROPER(TRIM(M10))) -> Platinum | R10: =IFERROR(VLOOKUP(TRIM(L10),State_Mapping!A:B,2,FALSE),"Unknown") -> New York | S10: =IF(C10="","Missing","Valid") -> Valid
A11: ORD103892 | B11: CUST004318 | C11: 2025-02-22 | D11: Online | E11: Completed | F11: Debit Card | G11: 12.99 | H11: 0 | I11: 130.99 | J11: Monica | K11: Williams | L11: NC | M11: BRONZE | N11: 2024-12-21 | O11: =IF(J11="","UNKNOWN",PROPER(TRIM(J11))) -> Monica | P11: =IF(K11="","UNKNOWN",PROPER(TRIM(K11))) -> Williams | Q11: =IF(M11="","UNKNOWN",PROPER(TRIM(M11))) -> Bronze | R11: =IFERROR(VLOOKUP(TRIM(L11),State_Mapping!A:B,2,FALSE),"Unknown") -> North Carolina | S11: =IF(C11="","Missing","Valid") -> Valid
A12: ORD118451 | B12: CUST004089 | C12: 2024-10-02 | D12: Online | E12: Completed | F12: Store Credit | G12: 0 | H12: 10 | I12: 1380.19 | J12: Laura | K12: Parrish | L12: Missouri | M12: Platinum | N12: 2022-08-31 | O12: =IF(J12="","UNKNOWN",PROPER(TRIM(J12))) -> Laura | P12: =IF(K12="","UNKNOWN",PROPER(TRIM(K12))) -> Parrish | Q12: =IF(M12="","UNKNOWN",PROPER(TRIM(M12))) -> Platinum | R12: =IFERROR(VLOOKUP(TRIM(L12),State_Mapping!A:B,2,FALSE),"Unknown") -> Missouri | S12: =IF(C12="","Missing","Valid") -> Valid
A13: ORD107271 | B13: CUST004048 | C13: 2024-01-09 | D13: Mobile App | E13: Completed | F13: Store Credit | G13: 7.99 | H13: 0 | I13: 944.14 | J13: Eric | K13: Mosley | L13: tx | M13: BRONZE | N13: 2020-10-21 | O13: =IF(J13="","UNKNOWN",PROPER(TRIM(J13))) -> Eric | P13: =IF(K13="","UNKNOWN",PROPER(TRIM(K13))) -> Mosley | Q13: =IF(M13="","UNKNOWN",PROPER(TRIM(M13))) -> Bronze | R13: =IFERROR(VLOOKUP(TRIM(L13),State_Mapping!A:B,2,FALSE),"Unknown") -> Texas | S13: =IF(C13="","Missing","Valid") -> Valid
A14: ORD117530 | B14: CUST000728 | C14: 2026-05-06 | D14: Mobile App | E14: Completed | F14: Credit Card | G14: 4.99 | H14: 20 | I14: 2023.4 | J14: Karen | K14: Scott | L14: CA | M14: bronze | N14: 2025-11-24 | O14: =IF(J14="","UNKNOWN",PROPER(TRIM(J14))) -> Karen | P14: =IF(K14="","UNKNOWN",PROPER(TRIM(K14))) -> Scott | Q14: =IF(M14="","UNKNOWN",PROPER(TRIM(M14))) -> Bronze | R14: =IFERROR(VLOOKUP(TRIM(L14),State_Mapping!A:B,2,FALSE),"Unknown") -> California | S14: =IF(C14="","Missing","Valid") -> Valid
A15: ORD105436 | B15: CUST000786 | C15: 2025-04-28 | D15: Online | E15: Completed | F15: Gift Card | G15: 7.99 | H15: 0 | I15: 1390.77 | J15: Bradley | K15: Cook | L15: Tennessee | M15: silver | N15: 2024-04-28 | O15: =IF(J15="","UNKNOWN",PROPER(TRIM(J15))) -> Bradley | P15: =IF(K15="","UNKNOWN",PROPER(TRIM(K15))) -> Cook | Q15: =IF(M15="","UNKNOWN",PROPER(TRIM(M15))) -> Silver | R15: =IFERROR(VLOOKUP(TRIM(L15),State_Mapping!A:B,2,FALSE),"Unknown") -> Tennessee | S15: =IF(C15="","Missing","Valid") -> Valid
A16: ORD123730 | B16: CUST002398 | C16: 2026-05-06 | D16: Online | E16: Completed | F16: Gift Card | G16: 0 | H16: 0 | I16: 3999.73 | J16: Matthew | K16: Blake | L16: AZ | M16: Bronze | N16: 2026-05-03 | O16: =IF(J16="","UNKNOWN",PROPER(TRIM(J16))) -> Matthew | P16: =IF(K16="","UNKNOWN",PROPER(TRIM(K16))) -> Blake | Q16: =IF(M16="","UNKNOWN",PROPER(TRIM(M16))) -> Bronze | R16: =IFERROR(VLOOKUP(TRIM(L16),State_Mapping!A:B,2,FALSE),"Unknown") -> Arizona | S16: =IF(C16="","Missing","Valid") -> Valid
A17: ORD121263 | B17: CUST003036 | C17: 2026-04-08 | D17: Mobile App | E17: Completed | F17: PayPal | G17: 4.99 | H17: 10 | I17: 1576.7 | J17: Frank | K17: Young | L17: MASSACHUSETTS | M17: BRONZE | N17: 2023-07-12 | O17: =IF(J17="","UNKNOWN",PROPER(TRIM(J17))) -> Frank | P17: =IF(K17="","UNKNOWN",PROPER(TRIM(K17))) -> Young | Q17: =IF(M17="","UNKNOWN",PROPER(TRIM(M17))) -> Bronze | R17: =IFERROR(VLOOKUP(TRIM(L17),State_Mapping!A:B,2,FALSE),"Unknown") -> Massachusetts | S17: =IF(C17="","Missing","Valid") -> Valid
A18: ORD110264 | B18: CUST001457 | C18: 2024-10-10 | D18: Mobile App | E18: COMPLETED | F18: Store Credit | G18: 5.99 | H18: 0 | I18: 2125.94 | J18: Danielle | K18: Kennedy | L18: Washington | M18: silver | N18: 2021-12-30 | O18: =IF(J18="","UNKNOWN",PROPER(TRIM(J18))) -> Danielle | P18: =IF(K18="","UNKNOWN",PROPER(TRIM(K18))) -> Kennedy | Q18: =IF(M18="","UNKNOWN",PROPER(TRIM(M18))) -> Silver | R18: =IFERROR(VLOOKUP(TRIM(L18),State_Mapping!A:B,2,FALSE),"Unknown") -> Washington | S18: =IF(C18="","Missing","Valid") -> Valid
A19: ORD106642 | B19: CUST004410 | C19: 2025-08-26 | D19: Mobile App | E19: Completed | F19: Debit Card | G19: 12.99 | H19: 20 | I19: 640.33 | J19: Shawn | K19: Norman | L19: NJ | M19: BRONZE | N19: 2022-10-04 | O19: =IF(J19="","UNKNOWN",PROPER(TRIM(J19))) -> Shawn | P19: =IF(K19="","UNKNOWN",PROPER(TRIM(K19))) -> Norman | Q19: =IF(M19="","UNKNOWN",PROPER(TRIM(M19))) -> Bronze | R19: =IFERROR(VLOOKUP(TRIM(L19),State_Mapping!A:B,2,FALSE),"Unknown") -> New Jersey | S19: =IF(C19="","Missing","Valid") -> Valid
A20: ORD100896 | B20: CUST004520 | C20: 2024-04-03 | D20: Mobile App | E20: Completed | F20: Store Credit | G20: 12.99 | H20: 0 | I20: 618.61 | J20: Bruce | K20: Brooks | L20: AZ | M20: GOLD | N20: 2021-06-26 | O20: =IF(J20="","UNKNOWN",PROPER(TRIM(J20))) -> Bruce | P20: =IF(K20="","UNKNOWN",PROPER(TRIM(K20))) -> Brooks | Q20: =IF(M20="","UNKNOWN",PROPER(TRIM(M20))) -> Gold | R20: =IFERROR(VLOOKUP(TRIM(L20),State_Mapping!A:B,2,FALSE),"Unknown") -> Arizona | S20: =IF(C20="","Missing","Valid") -> Valid
A21: ORD111349 | B21: CUST003485 | C21: 2022-12-21 | D21: Mobile App | E21: Returned | F21: PayPal | G21: 7.99 | H21: 15 | I21: 288.53 | J21: Dana | K21: Anderson | L21: Maryland | M21: Bronze | N21: 2022-10-09
A22: ORD102164 | B22: CUST005197 | C22: 2023-07-15 | D22: Online | E22: COMPLETED | F22: Gift Card | G22: 0 | H22: 0 | I22: 1502.65 | J22: Nicholas | K22: Reyes | L22: MASSACHUSETTS | M22: BRONZE | N22: 2021-04-05 | O22: =IF(J22="","UNKNOWN",PROPER(TRIM(J22))) -> Nicholas | P22: =IF(K22="","UNKNOWN",PROPER(TRIM(K22))) -> Reyes | Q22: =IF(M22="","UNKNOWN",PROPER(TRIM(M22))) -> Bronze | R22: =IFERROR(VLOOKUP(TRIM(L22),State_Mapping!A:B,2,FALSE),"Unknown") -> Massachusetts | S22: =IF(C22="","Missing","Valid") -> Valid
A23: ORD103099 | B23: CUST000943 | C23: 2026-03-24 | D23: In-Store | E23: Completed | F23: Store Credit | G23: 12.99 | H23: 0 | I23: 1462.85 | J23: Eric | K23: Hampton | L23: IN | M23: Gold | N23: 01/08/2023 | O23: =IF(J23="","UNKNOWN",PROPER(TRIM(J23))) -> Eric | P23: =IF(K23="","UNKNOWN",PROPER(TRIM(K23))) -> Hampton | Q23: =IF(M23="","UNKNOWN",PROPER(TRIM(M23))) -> Gold | R23: =IFERROR(VLOOKUP(TRIM(L23),State_Mapping!A:B,2,FALSE),"Unknown") -> Indiana | S23: =IF(C23="","Missing","Valid") -> Valid
A24: ORD101243 | B24: CUST001306 | C24: 2026-01-03 | D24: Mobile App | E24: Completed | F24: Credit Card | G24: 7.99 | H24: 0 | I24: 2336.59 | J24: Clarence | K24: Diaz | L24: MARYLAND | M24: Silver | N24: 2023-02-22 | O24: =IF(J24="","UNKNOWN",PROPER(TRIM(J24))) -> Clarence | P24: =IF(K24="","UNKNOWN",PROPER(TRIM(K24))) -> Diaz | Q24: =IF(M24="","UNKNOWN",PROPER(TRIM(M24))) -> Silver | R24: =IFERROR(VLOOKUP(TRIM(L24),State_Mapping!A:B,2,FALSE),"Unknown") -> Maryland | S24: =IF(C24="","Missing","Valid") -> Valid
A25: ORD104975 | B25: CUST003605 | C25: 2023-12-18 | D25: Mobile App | E25: Completed | F25: Gift Card | G25: 0 | H25: 0 | I25: 353.52 | J25: James | K25: George | L25: Illinois | M25: silver | N25: 2020-10-14 | O25: =IF(J25="","UNKNOWN",PROPER(TRIM(J25))) -> James | P25: =IF(K25="","UNKNOWN",PROPER(TRIM(K25))) -> George | Q25: =IF(M25="","UNKNOWN",PROPER(TRIM(M25))) -> Silver | R25: =IFERROR(VLOOKUP(TRIM(L25),State_Mapping!A:B,2,FALSE),"Unknown") -> Illinois | S25: =IF(C25="","Missing","Valid") -> Valid
A26: ORD126798 | B26: CUST002862 | C26: 2022-09-24 | D26: In-Store | E26: Completed | F26: Credit Card | G26: 4.99 | H26: 0 | I26: 850.54 | J26: Amy | K26: Alvarez | L26: ga | M26: gold | N26: 2022-02-17 | O26: =IF(J26="","UNKNOWN",PROPER(TRIM(J26))) -> Amy | P26: =IF(K26="","UNKNOWN",PROPER(TRIM(K26))) -> Alvarez | Q26: =IF(M26="","UNKNOWN",PROPER(TRIM(M26))) -> Gold | R26: =IFERROR(VLOOKUP(TRIM(L26),State_Mapping!A:B,2,FALSE),"Unknown") -> Georgia | S26: =IF(C26="","Missing","Valid") -> Valid
A27: ORD112498 | B27: CUST000920 | C27: 2024-09-03 | D27: Mobile App | E27: Completed | F27: Debit Card | G27: 0 | H27: 5 | I27: 781.66 | J27: Samuel | K27: Ayala | L27: Tennessee | M27: silver | N27: 2022-02-01 | O27: =IF(J27="","UNKNOWN",PROPER(TRIM(J27))) -> Samuel | P27: =IF(K27="","UNKNOWN",PROPER(TRIM(K27))) -> Ayala | Q27: =IF(M27="","UNKNOWN",PROPER(TRIM(M27))) -> Silver | R27: =IFERROR(VLOOKUP(TRIM(L27),State_Mapping!A:B,2,FALSE),"Unknown") -> Tennessee | S27: =IF(C27="","Missing","Valid") -> Valid
A28: ORD107493 | B28: CUST003048 | C28: 2024-05-21 | D28: Online | E28: Completed | F28: Store Credit | G28: 12.99 | H28: 0 | I28: 284.68 | J28: Matthew | K28: Bond | L28: Tennessee | M28: Silver | N28: 2024-03-06 | O28: =IF(J28="","UNKNOWN",PROPER(TRIM(J28))) -> Matthew | P28: =IF(K28="","UNKNOWN",PROPER(TRIM(K28))) -> Bond | Q28: =IF(M28="","UNKNOWN",PROPER(TRIM(M28))) -> Silver | R28: =IFERROR(VLOOKUP(TRIM(L28),State_Mapping!A:B,2,FALSE),"Unknown") -> Tennessee | S28: =IF(C28="","Missing","Valid") -> Valid
A29: ORD107844 | B29: CUST001240 | C29: 2022-11-01 | D29: In-Store | E29: Completed | F29: Debit Card | G29: 4.99 | H29: 0 | I29: 1879.32 | J29: Nicholas | K29: Gilmore | L29: Massachusetts | M29: Platinum | N29: 2022-05-30 | O29: =IF(J29="","UNKNOWN",PROPER(TRIM(J29))) -> Nicholas | P29: =IF(K29="","UNKNOWN",PROPER(TRIM(K29))) -> Gilmore | Q29: =IF(M29="","UNKNOWN",PROPER(TRIM(M29))) -> Platinum | R29: =IFERROR(VLOOKUP(TRIM(L29),State_Mapping!A:B,2,FALSE),"Unknown") -> Massachusetts | S29: =IF(C29="","Missing","Valid") -> Valid
A30: ORD123697 | B30: CUST000969 | C30: 2025-09-20 | D30: Mobile App | E30: Completed | F30: Store Credit | G30: 0 | H30: 10 | I30: 1766.19 | J30: Emily | K30: Garcia | L30: IN | M30: PLATINUM | N30: 08/30/2023 | O30: =IF(J30="","UNKNOWN",PROPER(TRIM(J30))) -> Emily | P30: =IF(K30="","UNKNOWN",PROPER(TRIM(K30))) -> Garcia | Q30: =IF(M30="","UNKNOWN",PROPER(TRIM(M30))) -> Platinum | R30: =IFERROR(VLOOKUP(TRIM(L30),State_Mapping!A:B,2,FALSE),"Unknown") -> Indiana | S30: =IF(C30="","Missing","Valid") -> Valid
A31: ORD106948 | B31: CUST001175 | C31: 2025-08-12 | D31: In-Store | E31: Completed | F31: Gift Card | G31: 0 | H31: 20 | I31: 1024.38 | J31: Lisa | K31: Christian | L31: Texas | M31: silver | N31: 2025-08-07 | O31: =IF(J31="","UNKNOWN",PROPER(TRIM(J31))) -> Lisa | P31: =IF(K31="","UNKNOWN",PROPER(TRIM(K31))) -> Christian | Q31: =IF(M31="","UNKNOWN",PROPER(TRIM(M31))) -> Silver | R31: =IFERROR(VLOOKUP(TRIM(L31),State_Mapping!A:B,2,FALSE),"Unknown") -> Texas | S31: =IF(C31="","Missing","Valid") -> Valid
A32: ORD123520 | B32: CUST001013 | C32: 2024-03-14 | D32: Online | E32: Completed | F32: Debit Card | G32: 4.99 | H32: 5 | I32: 610.86 | J32: Heather | K32: Yates | L32: CALIFORNIA | M32: silver | N32: 2024-02-26 | O32: =IF(J32="","UNKNOWN",PROPER(TRIM(J32))) -> Heather | P32: =IF(K32="","UNKNOWN",PROPER(TRIM(K32))) -> Yates | Q32: =IF(M32="","UNKNOWN",PROPER(TRIM(M32))) -> Silver | R32: =IFERROR(VLOOKUP(TRIM(L32),State_Mapping!A:B,2,FALSE),"Unknown") -> California | S32: =IF(C32="","Missing","Valid") -> Valid
A33: ORD105124 | B33: CUST004742 | C33: 2021-12-27 | D33: Mobile App | E33: Completed | F33: Credit Card | G33: 7.99 | H33: 15 | I33: 1902.07 | J33: Rebecca | K33: Adams | L33: Florida | M33: silver | N33: 2021-05-12 | O33: =IF(J33="","UNKNOWN",PROPER(TRIM(J33))) -> Rebecca | P33: =IF(K33="","UNKNOWN",PROPER(TRIM(K33))) -> Adams | Q33: =IF(M33="","UNKNOWN",PROPER(TRIM(M33))) -> Silver | R33: =IFERROR(VLOOKUP(TRIM(L33),State_Mapping!A:B,2,FALSE),"Unknown") -> Florida | S33: =IF(C33="","Missing","Valid") -> Valid
... A49: ORD109448 | B49: CUST000481 | C49: 2025-05-28 | D49: In-Store | E49: Completed | F49: Store Credit | G49: 5.99 | H49: 0 | I49: 1119.98 | J49: Michael | K49: Hahn | L49: FL | M49: Gold | N49: 02/10/2022 | O49: =IF(J49="","UNKNOWN",PROPER(TRIM(J49))) -> Michael | P49: =IF(K49="","UNKNOWN",PROPER(TRIM(K49))) -> Hahn | Q49: =IF(M49="","UNKNOWN",PROPER(TRIM(M49))) -> Gold | R49: =IFERROR(VLOOKUP(TRIM(L49),State_Mapping!A:B,2,FALSE),"Unknown") -> Florida | S49: =IF(C49="","Missing","Valid") -> Valid
A50: ORD108364 | B50: CUST002465 | C50: 2026-04-27 | D50: In-Store | E50: Returned | F50: Gift Card | G50: 0 | H50: 0 | I50: 5899.92 | J50: Karen | K50: Bowers | L50: Michigan | M50: silver | N50: 2025-02-07
A51: ORD125370 | B51: CUST004218 | C51: 2025-03-16 | D51: In-Store | E51: Completed | F51: Gift Card | G51: 0 | H51: 0 | I51: 483.49 | J51: Heather | K51: Delacruz | L51: OH | M51: Gold | N51: 2025-03-16 | O51: =IF(J51="","UNKNOWN",PROPER(TRIM(J51))) -> Heather | P51: =IF(K51="","UNKNOWN",PROPER(TRIM(K51))) -> Delacruz | Q51: =IF(M51="","UNKNOWN",PROPER(TRIM(M51))) -> Gold | R51: =IFERROR(VLOOKUP(TRIM(L51),State_Mapping!A:B,2,FALSE),"Unknown") -> Ohio | S51: =IF(C51="","Missing","Valid") -> Valid
A52: ORD118155 | B52: CUST004880 | C52: 2024-07-25 | D52: Mobile App | E52: Completed | F52: Debit Card | G52: 0 | H52: 0 | I52: 1977.74 | J52: Christopher | K52: Thomas | L52: WA | M52: Bronze | N52: 2022-08-14 | O52: =IF(J52="","UNKNOWN",PROPER(TRIM(J52))) -> Christopher | P52: =IF(K52="","UNKNOWN",PROPER(TRIM(K52))) -> Thomas | Q52: =IF(M52="","UNKNOWN",PROPER(TRIM(M52))) -> Bronze | R52: =IFERROR(VLOOKUP(TRIM(L52),State_Mapping!A:B,2,FALSE),"Unknown") -> Washington | S52: =IF(C52="","Missing","Valid") -> Valid
A53: ORD119007 | B53: CUST004242 | C53: 2026-03-02 | D53: Mobile App | E53: Completed | F53: Credit Card | G53: 7.99 | H53: 0 | I53: 1132.23 | J53: Laura | K53: Johnson | L53: New York | M53: silver | N53: 2025-10-29 | O53: =IF(J53="","UNKNOWN",PROPER(TRIM(J53))) -> Laura | P53: =IF(K53="","UNKNOWN",PROPER(TRIM(K53))) -> Johnson | Q53: =IF(M53="","UNKNOWN",PROPER(TRIM(M53))) -> Silver | R53: =IFERROR(VLOOKUP(TRIM(L53),State_Mapping!A:B,2,FALSE),"Unknown") -> New York | S53: =IF(C53="","Missing","Valid") -> Valid
A54: ORD104400 | B54: CUST004958 | C54: 2023-10-28 | D54: Online | E54: Completed | F54: PayPal | G54: 12.99 | H54: 0 | I54: 1830.32 | J54: Isaiah | K54: Collins | L54: Missouri | M54: BRONZE | N54: 2023-01-11 | O54: =IF(J54="","UNKNOWN",PROPER(TRIM(J54))) -> Isaiah | P54: =IF(K54="","UNKNOWN",PROPER(TRIM(K54))) -> Collins | Q54: =IF(M54="","UNKNOWN",PROPER(TRIM(M54))) -> Bronze | R54: =IFERROR(VLOOKUP(TRIM(L54),State_Mapping!A:B,2,FALSE),"Unknown") -> Missouri | S54: =IF(C54="","Missing","Valid") -> Valid
A55: ORD101202 | B55: CUST001573 | C55: 2024-11-04 | D55: In-Store | E55: completed | F55: Gift Card | G55: 7.99 | H55: 0 | I55: 710.37 | J55: Angela | K55: Boyd | L55: md | M55: gold | N55: 2024-10-05 | O55: =IF(J55="","UNKNOWN",PROPER(TRIM(J55))) -> Angela | P55: =IF(K55="","UNKNOWN",PROPER(TRIM(K55))) -> Boyd | Q55: =IF(M55="","UNKNOWN",PROPER(TRIM(M55))) -> Gold | R55: =IFERROR(VLOOKUP(TRIM(L55),State_Mapping!A:B,2,FALSE),"Unknown") -> Massachusetts | S55: =IF(C55="","Missing","Valid") -> Valid
...

Sheet OrderLines_Clean
A1: order_item_id | B1: order_id | C1: product_id | D1: quantity | E1: unit_price_at_purchase | F1: product_name | G1: category | H1: sub_category | I1: brand | J1: customer_id | K1: order_date | L1: channel | M1: order_status | N1: order_status_clean | O1: unit_price_status | P1: sub_category_clean | Q1: order_date_status
A2: OI502661 | B2: ORD124764 | C2: PROD1007 | D2: 1 | E2: 119.59 | F2: Meridian Basics Wellness X | G2: Beauty & Personal Care | H2: Wellness | I2: Meridian Basics | J2: CUST002442 | K2: 2024-01-03 | L2: Online | M2: Completed | N2: =IF(M2="","Unknown",PROPER(TRIM(M2))) -> Completed | O2: =IF(E2="","Missing","Valid") -> Valid | P2: =IF(H2="","Unknown",PROPER(TRIM(H2))) -> Wellness | Q2: =IF(K2="","Missing","Valid") -> Valid
A3: OI504251 | B3: ORD123647 | C3: PROD1066 | D3: 1 | E3: 92.95 | F3: Northfield Fragrance Max | G3: Beauty & Personal Care | H3: Fragrance | I3: Northfield | J3: CUST003540 | K3: 2025-04-09 | L3: Mobile App | M3: Completed | N3: =IF(M3="","Unknown",PROPER(TRIM(M3))) -> Completed | O3: =IF(E3="","Missing","Valid") -> Valid | P3: =IF(H3="","Unknown",PROPER(TRIM(H3))) -> Fragrance | Q3: =IF(K3="","Missing","Valid") -> Valid
A4: OI563095 | B4: ORD120357 | C4: PROD1033 | D4: 3 | E4: 147.37 | F4: Crestline Wellness Classic | G4: Beauty & Personal Care | H4: Wellness | I4: Crestline | J4: CUST003336 | K4: 2026-01-09 | L4: Online | M4: Completed | N4: =IF(M4="","Unknown",PROPER(TRIM(M4))) -> Completed | O4: =IF(E4="","Missing","Valid") -> Valid | P4: =IF(H4="","Unknown",PROPER(TRIM(H4))) -> Wellness | Q4: =IF(K4="","Missing","Valid") -> Valid
A5: OI508966 | B5: ORD109049 | C5: PROD1211 | D5: 1 | E5: 79.19 | F5: Amberly Bedding | G5: Home & Kitchen | H5: Bedding | I5: Amberly | J5: CUST004023 | K5: 2026-04-04 | L5: In-Store | M5: Completed | N5: =IF(M5="","Unknown",PROPER(TRIM(M5))) -> Completed | O5: =IF(E5="","Missing","Valid") -> Valid | P5: =IF(H5="","Unknown",PROPER(TRIM(H5))) -> Bedding | Q5: =IF(K5="","Missing","Valid") -> Valid
A6: OI533946 | B6: ORD127684 | C6: PROD1152 | D6: 3 | E6: 792.04 | F6: Vertex Smartphone Lite | G6: Electronics | H6: Smartphones | I6: Vertex | J6: CUST001077 | K6: 2025-03-21 | L6: Online | M6: Completed | N6: =IF(M6="","Unknown",PROPER(TRIM(M6))) -> Completed | O6: =IF(E6="","Missing","Valid") -> Valid | P6: =IF(H6="","Unknown",PROPER(TRIM(H6))) -> Smartphones | Q6: =IF(K6="","Missing","Valid") -> Valid
A7: OI540748 | B7: ORD121329 | C7: PROD1163 | D7: 1 | E7: 471.74 | F7: Pinecrest Small Appliances Essential | G7: Home & Kitchen | H7: Small Appliances | I7: Pinecrest | J7: CUST000441 | K7: 2025-12-06 | L7: Mobile App | M7: Completed | N7: =IF(M7="","Unknown",PROPER(TRIM(M7))) -> Completed | O7: =IF(E7="","Missing","Valid") -> Valid | P7: =IF(H7="","Unknown",PROPER(TRIM(H7))) -> Small Appliances | Q7: =IF(K7="","Missing","Valid") -> Valid
A8: OI524525 | B8: ORD104018 | C8: PROD1122 | D8: 3 | E8: 26.31 | F8: Solstice Headphones Essential | G8: Electronics | H8: Headphones | I8: Solstice | J8: CUST001843 | K8: 2024-06-27 | L8: Mobile App | M8: Cancelled | N8: =IF(M8="","Unknown",PROPER(TRIM(M8))) -> Cancelled | O8: =IF(E8="","Missing","Valid") -> Valid | P8: =IF(H8="","Unknown",PROPER(TRIM(H8))) -> Headphones | Q8: =IF(K8="","Missing","Valid") -> Valid
A9: OI504130 | B9: ORD118883 | C9: PROD1158 | D9: 2 | E9: 248.11 | F9: Pinecrest Accessories Plus | G9: Apparel | H9: Accessories | I9: Pinecrest | J9: CUST004873 | K9: 2024-02-15 | L9: Online | M9: Returned | N9: =IF(M9="","Unknown",PROPER(TRIM(M9))) -> Returned | O9: =IF(E9="","Missing","Valid") -> Valid | P9: =IF(H9="","Unknown",PROPER(TRIM(H9))) -> Accessories | Q9: =IF(K9="","Missing","Valid") -> Valid
A10: OI568470 | B10: ORD123588 | C10: PROD1106 | D10: 1 | E10: 419.77 | F10: Orion Team Sport Pro | G10: Sports & Outdoors | H10: Team Sports | I10: Orion | J10: CUST003497 | K10: 2023-11-29 | L10: In-Store | M10: Completed | N10: =IF(M10="","Unknown",PROPER(TRIM(M10))) -> Completed | O10: =IF(E10="","Missing","Valid") -> Valid | P10: =IF(H10="","Unknown",PROPER(TRIM(H10))) -> Team Sports | Q10: =IF(K10="","Missing","Valid") -> Valid
A11: OI571275 | B11: ORD101564 | C11: PROD1071 | D11: 1 | E11: 342.46 | F11: Crestline Cycling Plus | G11: Sports & Outdoors | H11: Cycling | I11: Crestline | J11: CUST002458 | K11: 2025-10-26 | L11: Online | M11: Completed | N11: =IF(M11="","Unknown",PROPER(TRIM(M11))) -> Completed | O11: =IF(E11="","Missing","Valid") -> Valid | P11: =IF(H11="","Unknown",PROPER(TRIM(H11))) -> Cycling | Q11: =IF(K11="","Missing","Valid") -> Valid
A12: OI511685 | B12: ORD100958 | C12: PROD1050 | D12: 1 | E12: 36.47 | F12: TrueForm Bedding Essential | G12: Home & Kitchen | H12: Bedding | I12: TrueForm | J12: CUST001439 | K12: 2021-09-12 | L12: Online | M12: Completed | N12: =IF(M12="","Unknown",PROPER(TRIM(M12))) -> Completed | O12: =IF(E12="","Missing","Valid") -> Valid | P12: =IF(H12="","Unknown",PROPER(TRIM(H12))) -> Bedding | Q12: =IF(K12="","Missing","Valid") -> Valid
A13: OI520686 | B13: ORD121250 | C13: PROD1011 | D13: 2 | E13: 215.43 | F13: Solstice Small Appliances Lite | G13: Home & Kitchen | H13: Small Appliances | I13: Solstice | J13: CUST002939 | K13: 2025-08-06 | L13: Mobile App | M13: Completed | N13: =IF(M13="","Unknown",PROPER(TRIM(M13))) -> Completed | O13: =IF(E13="","Missing","Valid") -> Valid | P13: =IF(H13="","Unknown",PROPER(TRIM(H13))) -> Small Appliances | Q13: =IF(K13="","Missing","Valid") -> Valid
... A39: OI519957 | B39: ORD113745 | C39: PROD1132 | D39: 1 | E39: 806.53 | F39: Pinecrest Haircare Essential | G39: Beauty & Personal Care | H39: Haircare | I39: Pinecrest | J39: CUST001315 | K39: 2026-06-05 | L39: Online | M39: Completed | N39: =IF(M39="","Unknown",PROPER(TRIM(M39))) -> Completed | O39: =IF(E39="","Missing","Valid") -> Valid | P39: =IF(H39="","Unknown",PROPER(TRIM(H39))) -> Haircare | Q39: =IF(K39="","Missing","Valid") -> Valid
A40: OI529577 | B40: ORD118514 | C40: PROD1109 | D40: 4 | F40: Vertex Decor Max | G40: Home & Kitchen | H40: Decor | I40: Vertex | J40: CUST000743 | K40: 2025-09-03 | L40: In-Store | M40: Completed | N40: =IF(M40="","Unknown",PROPER(TRIM(M40))) -> Completed | O40: =IF(E40="","Missing","Valid") -> Missing | P40: =IF(H40="","Unknown",PROPER(TRIM(H40))) -> Decor | Q40: =IF(K40="","Missing","Valid") -> Valid
A41: OI554265 | B41: ORD114522 | C41: PROD1140 | D41: 3 | E41: 629.46 | F41: TrueForm Furniture Classic | G41: Home & Kitchen | H41: Furniture | I41: TrueForm | J41: CUST003690 | K41: 2025-11-20 | L41: In-Store | M41: Completed | N41: =IF(M41="","Unknown",PROPER(TRIM(M41))) -> Completed | O41: =IF(E41="","Missing","Valid") -> Valid | P41: =IF(H41="","Unknown",PROPER(TRIM(H41))) -> Furniture | Q41: =IF(K41="","Missing","Valid") -> Valid
A42: OI512680 | B42: ORD105058 | C42: PROD1128 | D42: 1 | E42: 876.84 | F42: Pinecrest Haircare Lite | G42: Beauty & Personal Care | H42: Haircare | I42: Pinecrest | J42: CUST003644 | K42: 2026-01-11 | L42: Online | M42: Completed | N42: =IF(M42="","Unknown",PROPER(TRIM(M42))) -> Completed | O42: =IF(E42="","Missing","Valid") -> Valid | P42: =IF(H42="","Unknown",PROPER(TRIM(H42))) -> Haircare | Q42: =IF(K42="","Missing","Valid") -> Valid
A43: OI528901 | B43: ORD122252 | C43: PROD1186 | D43: 2 | E43: 91.47 | F43: Lumen Smart Home | G43: Electronics | H43: Smart Home | I43: Lumen | J43: CUST005202 | K43: 2025-07-25 | L43: Online | M43: Returned | N43: =IF(M43="","Unknown",PROPER(TRIM(M43))) -> Returned | O43: =IF(E43="","Missing","Valid") -> Valid | P43: =IF(H43="","Unknown",PROPER(TRIM(H43))) -> Smart Home | Q43: =IF(K43="","Missing","Valid") -> Valid
A44: OI549605 | B44: ORD112541 | C44: PROD1035 | D44: 1 | E44: 489.75 | F44: Meridian Basics Women's Clothing Pro | G44: Apparel | H44: Women's Clothing | I44: Meridian Basics | J44: CUST005791 | K44: 2026-03-10 | L44: Online | M44: Completed | N44: =IF(M44="","Unknown",PROPER(TRIM(M44))) -> Completed | O44: =IF(E44="","Missing","Valid") -> Valid | P44: =IF(H44="","Unknown",PROPER(TRIM(H44))) -> Women'S Clothing | Q44: =IF(K44="","Missing","Valid") -> Valid
A45: OI528722 | B45: ORD108696 | C45: PROD1187 | D45: 1 | E45: 57.19 | F45: Meridian Basics Fitness Equipment Classic | G45: Sports & Outdoors | H45: Fitness Equipment | I45: Meridian Basics | J45: CUST005743 | K45: 2026-04-16 | L45: Mobile App | M45: COMPLETED | N45: =IF(M45="","Unknown",PROPER(TRIM(M45))) -> Completed | O45: =IF(E45="","Missing","Valid") -> Valid | P45: =IF(H45="","Unknown",PROPER(TRIM(H45))) -> Fitness Equipment | Q45: =IF(K45="","Missing","Valid") -> Valid
A46: OI569949 | B46: ORD126210 | C46: PROD1133 | D46: 1 | E46: 657.83 | F46: Meridian Basics Smart Home Essential | G46: Electronics | H46: Smart Home | I46: Meridian Basics | J46: CUST000126 | K46: 2024-03-23 | L46: Mobile App | M46: Completed | N46: =IF(M46="","Unknown",PROPER(TRIM(M46))) -> Completed | O46: =IF(E46="","Missing","Valid") -> Valid | P46: =IF(H46="","Unknown",PROPER(TRIM(H46))) -> Smart Home | Q46: =IF(K46="","Missing","Valid") -> Valid
A47: OI559224 | B47: ORD103817 | C47: PROD1095 | D47: 1 | E47: 106.61 | F47: Sabre Cycling X | G47: Sports & Outdoors | H47: Cycling | I47: Sabre | J47: CUST004084 | K47: 2023-04-21 | L47: Mobile App | M47: Completed | N47: =IF(M47="","Unknown",PROPER(TRIM(M47))) -> Completed | O47: =IF(E47="","Missing","Valid") -> Valid | P47: =IF(H47="","Unknown",PROPER(TRIM(H47))) -> Cycling | Q47: =IF(K47="","Missing","Valid") -> Valid
A48: OI519731 | B48: ORD120516 | C48: PROD1128 | D48: 2 | E48: 869.4 | F48: Pinecrest Haircare Lite | G48: Beauty & Personal Care | H48: Haircare | I48: Pinecrest | J48: CUST000457 | K48: 2026-06-03 | L48: Mobile App | M48: Completed | N48: =IF(M48="","Unknown",PROPER(TRIM(M48))) -> Completed | O48: =IF(E48="","Missing","Valid") -> Valid | P48: =IF(H48="","Unknown",PROPER(TRIM(H48))) -> Haircare | Q48: =IF(K48="","Missing","Valid") -> Valid
A49: OI554521 | B49: ORD115310 | C49: PROD1015 | D49: 1 | E49: 379.13 | F49: Lumen Cookware Lite | G49: Home & Kitchen | H49: Cookware | I49: Lumen | J49: CUST002357 | K49: 2026-01-08 | L49: Online | M49: Cancelled | N49: =IF(M49="","Unknown",PROPER(TRIM(M49))) -> Cancelled | O49: =IF(E49="","Missing","Valid") -> Valid | P49: =IF(H49="","Unknown",PROPER(TRIM(H49))) -> Cookware | Q49: =IF(K49="","Missing","Valid") -> Valid
A50: OI511425 | B50: ORD116255 | C50: PROD1165 | D50: 1 | E50: 348.8 | F50: Solstice Smartphones Plus | G50: Electronics | H50: Smartphones | I50: Solstice | J50: CUST000082 | K50: 2026-04-08 | L50: Online | M50: Completed | N50: =IF(M50="","Unknown",PROPER(TRIM(M50))) -> Completed | O50: =IF(E50="","Missing","Valid") -> Valid | P50: =IF(H50="","Unknown",PROPER(TRIM(H50))) -> Smartphones | Q50: =IF(K50="","Missing","Valid") -> Valid
A51: OI556807 | B51: ORD115207 | C51: PROD1209 | D51: 1 | E51: 654.81 | F51: Northfield Women's Clothing Lite | G51: Apparel | H51: Women's Clothing | I51: Northfield | J51: CUST001879 | K51: 2024-09-22 | L51: In-Store | M51: completed | N51: =IF(M51="","Unknown",PROPER(TRIM(M51))) -> Completed | O51: =IF(E51="","Missing","Valid") -> Valid | P51: =IF(H51="","Unknown",PROPER(TRIM(H51))) -> Women'S Clothing | Q51: =IF(K51="","Missing","Valid") -> Valid
A52: OI506530 | B52: ORD119893 | C52: PROD1077 | D52: 1 | E52: 646.09 | F52: TrueForm Women's Clothing Max | G52: Apparel | H52: Women's Clothing | I52: TrueForm | J52: CUST005716 | K52: 2026-01-19 | L52: Online | M52: Pending | N52: =IF(M52="","Unknown",PROPER(TRIM(M52))) -> Pending | O52: =IF(E52="","Missing","Valid") -> Valid | P52: =IF(H52="","Unknown",PROPER(TRIM(H52))) -> Women'S Clothing | Q52: =IF(K52="","Missing","Valid") -> Valid
... A55: OI559647 | B55: ORD115661 | C55: PROD1094 | D55: 2 | E55: 343.71 | F55: Lumen Women's Clothing Classic | G55: Apparel | H55: Women's Clothing | I55: Lumen | J55: CUST004054 | K55: 2025-08-06 | L55: In-Store | M55: Completed | N55: =IF(M55="","Unknown",PROPER(TRIM(M55))) -> Completed | O55: =IF(E55="","Missing","Valid") -> Valid | P55: =IF(H55="","Unknown",PROPER(TRIM(H55))) -> Women'S Clothing | Q55: =IF(K55="","Missing","Valid") -> Valid
A56: OI527662 | B56: ORD121895 | C56: PROD1012 | D56: 2 | F56: Northfield Cycling Lite | G56: Sports & Outdoors | H56: Cycling | I56: Northfield | J56: CUST000670 | K56: 2025-07-30 | L56: Mobile App | M56: Completed | N56: =IF(M56="","Unknown",PROPER(TRIM(M56))) -> Completed | O56: =IF(E56="","Missing","Valid") -> Missing | P56: =IF(H56="","Unknown",PROPER(TRIM(H56))) -> Cycling | Q56: =IF(K56="","Missing","Valid") -> Valid
A57: OI542769 | B57: ORD124235 | C57: PROD1097 | D57: 1 | E57: 251.04 | F57: BrightPath Accessories Plus | G57: Apparel | H57: Accessories | I57: BrightPath | J57: CUST003734 | K57: 2025-08-21 | L57: Mobile App | M57: Completed | N57: =IF(M57="","Unknown",PROPER(TRIM(M57))) -> Completed | O57: =IF(E57="","Missing","Valid") -> Valid | P57: =IF(H57="","Unknown",PROPER(TRIM(H57))) -> Accessories | Q57: =IF(K57="","Missing","Valid") -> Valid
A58: OI505245 | B58: ORD109973 | C58: PROD1126 | D58: 1 | E58: 600.34 | F58: Orion Laptops Essential | G58: Electronics | H58: Laptops | I58: Orion | J58: CUST002084 | K58: 2025-10-10 | L58: Mobile App | M58: Completed | N58: =IF(M58="","Unknown",PROPER(TRIM(M58))) -> Completed | O58: =IF(E58="","Missing","Valid") -> Valid | P58: =IF(H58="","Unknown",PROPER(TRIM(H58))) -> Laptops | Q58: =IF(K58="","Missing","Valid") -> Valid
A59: OI547743 | B59: ORD101716 | C59: PROD1045 | D59: 1 | E59: 116.65 | F59: Sabre Furniture | G59: Home & Kitchen | H59: Furniture | I59: Sabre | J59: CUST003035 | K59: 2026-03-30 | L59: In-Store | M59: Completed | N59: =IF(M59="","Unknown",PROPER(TRIM(M59))) -> Completed | O59: =IF(E59="","Missing","Valid") -> Valid | P59: =IF(H59="","Unknown",PROPER(TRIM(H59))) -> Furniture | Q59: =IF(K59="","Missing","Valid") -> Valid
A60: OI536586 | B60: ORD104480 | C60: PROD1174 | D60: 1 | E60: 331.83 | F60: TrueForm Tablet | G60: Electronics | H60: Tablets | I60: TrueForm | J60: CUST001871 | K60: 2024-06-11 | L60: In-Store | M60: Completed | N60: =IF(M60="","Unknown",PROPER(TRIM(M60))) -> Completed | O60: =IF(E60="","Missing","Valid") -> Valid | P60: =IF(H60="","Unknown",PROPER(TRIM(H60))) -> Tablets | Q60: =IF(K60="","Missing","Valid") -> Valid
A61: OI501685 | B61: ORD119580 | C61: PROD1013 | D61: 1 | E61: 166.51 | F61: TrueForm Fragrance | G61: Beauty & Personal Care | H61: Fragrance | I61: TrueForm | J61: CUST003443 | K61: 2025-03-09 | L61: Mobile App | M61: Completed | N61: =IF(M61="","Unknown",PROPER(TRIM(M61))) -> Completed | O61: =IF(E61="","Missing","Valid") -> Valid | P61: =IF(H61="","Unknown",PROPER(TRIM(H61))) -> Fragrance | Q61: =IF(K61="","Missing","Valid") -> Valid
A62: OI504903 | B62: ORD118748 | C62: PROD1150 | D62: 1 | E62: 51.07 | F62: Pinecrest Skincare Classic | G62: Beauty & Personal Care | H62: Skincare | I62: Pinecrest | J62: CUST003723 | K62: 2024-12-10 | L62: Online | M62: Completed | N62: =IF(M62="","Unknown",PROPER(TRIM(M62))) -> Completed | O62: =IF(E62="","Missing","Valid") -> Valid | P62: =IF(H62="","Unknown",PROPER(TRIM(H62))) -> Skincare | Q62: =IF(K62="","Missing","Valid") -> Valid
A63: OI555894 | B63: ORD117781 | C63: PROD1024 | D63: 1 | E63: 335.28 | F63: Pinecrest Skincare Classic | G63: Beauty & Personal Care | H63: Skincare | I63: Pinecrest | J63: CUST003107 | K63: 2025-01-24 | L63: Online | M63: Completed | N63: =IF(M63="","Unknown",PROPER(TRIM(M63))) -> Completed | O63: =IF(E63="","Missing","Valid") -> Valid | P63: =IF(H63="","Unknown",PROPER(TRIM(H63))) -> Skincare | Q63: =IF(K63="","Missing","Valid") -> Valid
A64: OI551522 | B64: ORD107102 | C64: PROD1031 | D64: 1 | E64: 593.48 | F64: Lumen Cookware Essential | G64: Home & Kitchen | H64: Cookware | I64: Lumen | J64: CUST005612 | K64: 2023-10-04 | L64: In-Store | M64: COMPLETED | N64: =IF(M64="","Unknown",PROPER(TRIM(M64))) -> Completed | O64: =IF(E64="","Missing","Valid") -> Valid | P64: =IF(H64="","Unknown",PROPER(TRIM(H64))) -> Cookware | Q64: =IF(K64="","Missing","Valid") -> Valid
A65: OI508042 | B65: ORD123000 | C65: PROD1006 | D65: 3 | E65: 526.81 | F65: Crestline Decor | G65: Home & Kitchen | H65: Decor | I65: Crestline | J65: CUST002434 | K65: 2022-05-08 | L65: In-Store | M65: Completed | N65: =IF(M65="","Unknown",PROPER(TRIM(M65))) -> Completed | O65: =IF(E65="","Missing","Valid") -> Valid | P65: =IF(H65="","Unknown",PROPER(TRIM(H65))) -> Decor | Q65: =IF(K65="","Missing","Valid") -> Valid
A66: OI538826 | B66: ORD103387 | C66: PROD1204 | D66: 1 | E66: 516.67 | F66: Lumen Small Appliance X | G66: Home & Kitchen | H66: Small Appliances | I66: Lumen | J66: CUST004681 | K66: 2025-04-09 | L66: Mobile App | M66: Completed | N66: =IF(M66="","Unknown",PROPER(TRIM(M66))) -> Completed | O66: =IF(E66="","Missing","Valid") -> Valid | P66: =IF(H66="","Unknown",PROPER(TRIM(H66))) -> Small Appliances | Q66: =IF(K66="","Missing","Valid") -> Valid
A67: OI533660 | B67: ORD123574 | C67: PROD1125 | D67: 1 | E67: 221.84 | F67: Northfield Team Sports Pro | G67: Sports & Outdoors | H67: Team Sports | I67: Northfield | J67: CUST005151 | K67: 2026-02-21 | L67: Online | M67: Completed | N67: =IF(M67="","Unknown",PROPER(TRIM(M67))) -> Completed | O67: =IF(E67="","Missing","Valid") -> Valid | P67: =IF(H67="","Unknown",PROPER(TRIM(H67))) -> Team Sports | Q67: =IF(K67="","Missing","Valid") -> Valid
...

Sheet State_Mapping
A1: Original | B1: Standardized
A2: Indiana | B2: Indiana
A3: WISCONSIN | B3: Wisconsin
A4: GA | B4: Georgia
A5: PA | B5: Pennsylvania
A6: NY | B6: New York
A7: Wisconsin | B7: Wisconsin
A8: OH | B8: Ohio
A9: Michigan | B9: Michigan
A10: New York | B10: New York
A11: NC | B11: North Carolina
A12: Missouri | B12: Missouri
... A81: INDIANA | B81: Indiana

Sheet Descriptive_Stats
A1: Statistic | B1: Order Value | C1: Shipping Cost
A2: Mean | B2: =AVERAGE(Orders_Clean!I2:I1000) -> 1547.2997 | C2: =AVERAGE(Orders_Clean!G2:G1000) -> 5.2116575
A3: Median | B3: =MEDIAN(Orders_Clean!I2:I1000) -> 1278.85 | C3: =MEDIAN(Orders_Clean!G2:G1000) -> 4.99
A4: Standard Deviation | B4: =STDEV(Orders_Clean!I2:I1000) -> 1178.7747 | C4: =STDEV(Orders_Clean!G2:G1000) -> 4.4820307
A5: Minimum | B5: =MIN(Orders_Clean!I2:I1000) -> 12.1 | C5: =MIN(Orders_Clean!G2:G1000) -> 0
A6: maximum | B6: =MAX(Orders_Clean!I2:I1000) -> 8688.53 | C6: =MAX(Orders_Clean!G2:G1000) -> 12.99

Sheet Pivot_Category_Channel

Sheet Pivot_Revenue_State_Tier

Sheet Data_Quality_Log
A1: DOCUMENT OF DATA-QUALITY ISSUES
A3: Sheet | B3: Column | C3: Issue | D3: Formula | E3: Decision | F3: Justification
A4: Orders | B4: first_name | C4: Extra spaces | D4: TRIM() | E4: Cleaned | F4: Ensures consistency
A5: Orders | B5: order_status | C5: Mixed casing | D5: PROPER(TRIM()) | E5: Standardized | F5: Prevents duplicate categories
A6: Orders | B6: membership_tier | C6: Mixed casing | D6: PROPER(TRIM()) | E6: Standardized | F6: Supports accurate grouping
A7: Orders | B7: state | C7: Abbreviations/full names | D7: VLOOKUP() | E7: Standardized | F7: Prevents duplicate geographic groups
A8: Orders | B8: order_date | C8: Missing values | D8: IF() flag | E8: Flagged | F8: Dates should not be fabricated
A9: OrderLines | B9: unit_price | C9: Missing values | D9: IF() flag | E9: Flagged | F9: Missing ≠ zero
A10: OrderLines | B10: sub_category | C10: Missing values | D10: IF() | E10: Unknown | F10: Avoid guessing categories
A11: OrderLines | B11: order_status | C11: Mixed casing | D11: PROPER(TRIM()) | E11: Standardized | F11: Ensures consistency
